Workbook

Sheet Dashboard
A1: Rental Property Dashboard (Sample Data) | J1: PropertyList
J2: All
A3: Property Filter: | B3: All | J3: P001
D4: Monthly Summary (2025) | J4: P002
A5: Total Units | B5: =IF($B$3="All",COUNTA(Units!$A$2:$A$1000),COUNTIF(Units!$B:$B,$B$3)) -> 18 | D5: Month | E5: Rent Due | F5: Rent Collected | G5: Outstanding | H5: On-time % | J5: P003
A6: Occupied Units | B6: =IF($B$3="All",COUNTIF(Units!$I:$I,"Occupied"),COUNTIFS(Units!$B:$B,$B$3,Units!$I:$I,"Occupied")) -> 14 | D6: 45658 | E6: =IF($B$3="All",SUMIFS(RentPayments!$G:$G,RentPayments!$E:$E,">="&DATE(2025,1,1),RentPayments!$E:$E,"<="&EOMONTH(DATE(2025,1,1),0)),SUMIFS(RentPayments!$G:$G,RentPayments!$D:$D,$B$3,RentPayments!$E:$E,">="&DATE(2025,1,1),RentPayments!$E:$E,"<="&EOMONTH(DATE(2025,1,1),0))) -> 16150 | F6: =IF($B$3="All",SUMIFS(RentPayments!$H:$H,RentPayments!$E:$E,">="&DATE(2025,1,1),RentPayments!$E:$E,"<="&EOMONTH(DATE(2025,1,1),0)),SUMIFS(RentPayments!$H:$H,RentPayments!$D:$D,$B$3,RentPayments!$E:$E,">="&DATE(2025,1,1),RentPayments!$E:$E,"<="&EOMONTH(DATE(2025,1,1),0))) -> 16150 | G6: =E6-F6 -> 0 | H6: 0.42857144
A7: Occupancy Rate | B7: =IFERROR(B6/B5,0) -> 0.77777778 | D7: 45689 | E7: =IF($B$3="All",SUMIFS(RentPayments!$G:$G,RentPayments!$E:$E,">="&DATE(2025,2,1),RentPayments!$E:$E,"<="&EOMONTH(DATE(2025,2,1),0)),SUMIFS(RentPayments!$G:$G,RentPayments!$D:$D,$B$3,RentPayments!$E:$E,">="&DATE(2025,2,1),RentPayments!$E:$E,"<="&EOMONTH(DATE(2025,2,1),0))) -> 16150 | F7: =IF($B$3="All",SUMIFS(RentPayments!$H:$H,RentPayments!$E:$E,">="&DATE(2025,2,1),RentPayments!$E:$E,"<="&EOMONTH(DATE(2025,2,1),0)),SUMIFS(RentPayments!$H:$H,RentPayments!$D:$D,$B$3,RentPayments!$E:$E,">="&DATE(2025,2,1),RentPayments!$E:$E,"<="&EOMONTH(DATE(2025,2,1),0))) -> 15762.5 | G7: =E7-F7 -> 387.5 | H7: 0.5
A8: Rent Due (2025) | B8: =IF($B$3="All",SUM(RentPayments!$G:$G),SUMIF(RentPayments!$D:$D,$B$3,RentPayments!$G:$G)) -> 138850 | D8: 45717 | E8: =IF($B$3="All",SUMIFS(RentPayments!$G:$G,RentPayments!$E:$E,">="&DATE(2025,3,1),RentPayments!$E:$E,"<="&EOMONTH(DATE(2025,3,1),0)),SUMIFS(RentPayments!$G:$G,RentPayments!$D:$D,$B$3,RentPayments!$E:$E,">="&DATE(2025,3,1),RentPayments!$E:$E,"<="&EOMONTH(DATE(2025,3,1),0))) -> 16150 | F8: =IF($B$3="All",SUMIFS(RentPayments!$H:$H,RentPayments!$E:$E,">="&DATE(2025,3,1),RentPayments!$E:$E,"<="&EOMONTH(DATE(2025,3,1),0)),SUMIFS(RentPayments!$H:$H,RentPayments!$D:$D,$B$3,RentPayments!$E:$E,">="&DATE(2025,3,1),RentPayments!$E:$E,"<="&EOMONTH(DATE(2025,3,1),0))) -> 15862.5 | G8: =E8-F8 -> 287.5 | H8: 0.35714286
A9: Rent Collected (2025) | B9: =IF($B$3="All",SUM(RentPayments!$H:$H),SUMIF(RentPayments!$D:$D,$B$3,RentPayments!$H:$H)) -> 133987.5 | D9: 45748 | E9: =IF($B$3="All",SUMIFS(RentPayments!$G:$G,RentPayments!$E:$E,">="&DATE(2025,4,1),RentPayments!$E:$E,"<="&EOMONTH(DATE(2025,4,1),0)),SUMIFS(RentPayments!$G:$G,RentPayments!$D:$D,$B$3,RentPayments!$E:$E,">="&DATE(2025,4,1),RentPayments!$E:$E,"<="&EOMONTH(DATE(2025,4,1),0))) -> 16150 | F9: =IF($B$3="All",SUMIFS(RentPayments!$H:$H,RentPayments!$E:$E,">="&DATE(2025,4,1),RentPayments!$E:$E,"<="&EOMONTH(DATE(2025,4,1),0)),SUMIFS(RentPayments!$H:$H,RentPayments!$D:$D,$B$3,RentPayments!$E:$E,">="&DATE(2025,4,1),RentPayments!$E:$E,"<="&EOMONTH(DATE(2025,4,1),0))) -> 16150 | G9: =E9-F9 -> 0 | H9: 0.42857144
A10: Outstanding Rent | B10: =B9-B10 | D10: 45778 | E10: =IF($B$3="All",SUMIFS(RentPayments!$G:$G,RentPayments!$E:$E,">="&DATE(2025,5,1),RentPayments!$E:$E,"<="&EOMONTH(DATE(2025,5,1),0)),SUMIFS(RentPayments!$G:$G,RentPayments!$D:$D,$B$3,RentPayments!$E:$E,">="&DATE(2025,5,1),RentPayments!$E:$E,"<="&EOMONTH(DATE(2025,5,1),0))) -> 16150 | F10: =IF($B$3="All",SUMIFS(RentPayments!$H:$H,RentPayments!$E:$E,">="&DATE(2025,5,1),RentPayments!$E:$E,"<="&EOMONTH(DATE(2025,5,1),0)),SUMIFS(RentPayments!$H:$H,RentPayments!$D:$D,$B$3,RentPayments!$E:$E,">="&DATE(2025,5,1),RentPayments!$E:$E,"<="&EOMONTH(DATE(2025,5,1),0))) -> 14587.5 | G10: =E10-F10 -> 1562.5 | H10: 0.28571429
A11: Maintenance Cost (2025) | B11: =IF($B$3="All",SUM(Maintenance!$H:$H),SUMIF(Maintenance!$B:$B,$B$3,Maintenance!$H:$H)) -> 15374.55 | D11: 45809 | E11: =IF($B$3="All",SUMIFS(RentPayments!$G:$G,RentPayments!$E:$E,">="&DATE(2025,6,1),RentPayments!$E:$E,"<="&EOMONTH(DATE(2025,6,1),0)),SUMIFS(RentPayments!$G:$G,RentPayments!$D:$D,$B$3,RentPayments!$E:$E,">="&DATE(2025,6,1),RentPayments!$E:$E,"<="&EOMONTH(DATE(2025,6,1),0))) -> 16150 | F11: =IF($B$3="All",SUMIFS(RentPayments!$H:$H,RentPayments!$E:$E,">="&DATE(2025,6,1),RentPayments!$E:$E,"<="&EOMONTH(DATE(2025,6,1),0)),SUMIFS(RentPayments!$H:$H,RentPayments!$D:$D,$B$3,RentPayments!$E:$E,">="&DATE(2025,6,1),RentPayments!$E:$E,"<="&EOMONTH(DATE(2025,6,1),0))) -> 16150 | G11: =E11-F11 -> 0 | H11: 0.42857144
A12: Other Expenses (2025) | B12: =IF($B$3="All",SUM(Expenses!$E:$E),SUMIF(Expenses!$B:$B,$B$3,Expenses!$E:$E)) -> 33706.12 | D12: 45839 | E12: =IF($B$3="All",SUMIFS(RentPayments!$G:$G,RentPayments!$E:$E,">="&DATE(2025,7,1),RentPayments!$E:$E,"<="&EOMONTH(DATE(2025,7,1),0)),SUMIFS(RentPayments!$G:$G,RentPayments!$D:$D,$B$3,RentPayments!$E:$E,">="&DATE(2025,7,1),RentPayments!$E:$E,"<="&EOMONTH(DATE(2025,7,1),0))) -> 12700 | F12: =IF($B$3="All",SUMIFS(RentPayments!$H:$H,RentPayments!$E:$E,">="&DATE(2025,7,1),RentPayments!$E:$E,"<="&EOMONTH(DATE(2025,7,1),0)),SUMIFS(RentPayments!$H:$H,RentPayments!$D:$D,$B$3,RentPayments!$E:$E,">="&DATE(2025,7,1),RentPayments!$E:$E,"<="&EOMONTH(DATE(2025,7,1),0))) -> 10600 | G12: =E12-F12 -> 2100 | H12: 0.18181818
A13: Net Income (simple) | B13: =B10-B12-B13 | D13: 45870 | E13: =IF($B$3="All",SUMIFS(RentPayments!$G:$G,RentPayments!$E:$E,">="&DATE(2025,8,1),RentPayments!$E:$E,"<="&EOMONTH(DATE(2025,8,1),0)),SUMIFS(RentPayments!$G:$G,RentPayments!$D:$D,$B$3,RentPayments!$E:$E,">="&DATE(2025,8,1),RentPayments!$E:$E,"<="&EOMONTH(DATE(2025,8,1),0))) -> 9150 | F13: =IF($B$3="All",SUMIFS(RentPayments!$H:$H,RentPayments!$E:$E,">="&DATE(2025,8,1),RentPayments!$E:$E,"<="&EOMONTH(DATE(2025,8,1),0)),SUMIFS(RentPayments!$H:$H,RentPayments!$D:$D,$B$3,RentPayments!$E:$E,">="&DATE(2025,8,1),RentPayments!$E:$E,"<="&EOMONTH(DATE(2025,8,1),0))) -> 9150 | G13: =E13-F13 -> 0 | H13: 0.375
D14: 45901 | E14: =IF($B$3="All",SUMIFS(RentPayments!$G:$G,RentPayments!$E:$E,">="&DATE(2025,9,1),RentPayments!$E:$E,"<="&EOMONTH(DATE(2025,9,1),0)),SUMIFS(RentPayments!$G:$G,RentPayments!$D:$D,$B$3,RentPayments!$E:$E,">="&DATE(2025,9,1),RentPayments!$E:$E,"<="&EOMONTH(DATE(2025,9,1),0))) -> 7900 | F14: =IF($B$3="All",SUMIFS(RentPayments!$H:$H,RentPayments!$E:$E,">="&DATE(2025,9,1),RentPayments!$E:$E,"<="&EOMONTH(DATE(2025,9,1),0)),SUMIFS(RentPayments!$H:$H,RentPayments!$D:$D,$B$3,RentPayments!$E:$E,">="&DATE(2025,9,1),RentPayments!$E:$E,"<="&EOMONTH(DATE(2025,9,1),0))) -> 7687.5 | G14: =E14-F14 -> 212.5 | H14: 0.71428572
D15: 45962 | E15: =IF($B$3="All",SUMIFS(RentPayments!$G:$G,RentPayments!$E:$E,">="&DATE(2025,11,1),RentPayments!$E:$E,"<="&EOMONTH(DATE(2025,11,1),0)),SUMIFS(RentPayments!$G:$G,RentPayments!$D:$D,$B$3,RentPayments!$E:$E,">="&DATE(2025,11,1),RentPayments!$E:$E,"<="&EOMONTH(DATE(2025,11,1),0))) -> 3800 | F15: =IF($B$3="All",SUMIFS(RentPayments!$H:$H,RentPayments!$E:$E,">="&DATE(2025,11,1),RentPayments!$E:$E,"<="&EOMONTH(DATE(2025,11,1),0)),SUMIFS(RentPayments!$H:$H,RentPayments!$D:$D,$B$3,RentPayments!$E:$E,">="&DATE(2025,11,1),RentPayments!$E:$E,"<="&EOMONTH(DATE(2025,11,1),0))) -> 3800 | G15: =E15-F15 -> 0 | H15: 0
D16: 45992 | E16: =IF($B$3="All",SUMIFS(RentPayments!$G:$G,RentPayments!$E:$E,">="&DATE(2025,12,1),RentPayments!$E:$E,"<="&EOMONTH(DATE(2025,12,1),0)),SUMIFS(RentPayments!$G:$G,RentPayments!$D:$D,$B$3,RentPayments!$E:$E,">="&DATE(2025,12,1),RentPayments!$E:$E,"<="&EOMONTH(DATE(2025,12,1),0))) -> 1700 | F16: =IF($B$3="All",SUMIFS(RentPayments!$H:$H,RentPayments!$E:$E,">="&DATE(2025,12,1),RentPayments!$E:$E,"<="&EOMONTH(DATE(2025,12,1),0)),SUMIFS(RentPayments!$H:$H,RentPayments!$D:$D,$B$3,RentPayments!$E:$E,">="&DATE(2025,12,1),RentPayments!$E:$E,"<="&EOMONTH(DATE(2025,12,1),0))) -> 1700 | G16: =E16-F16 -> 0 | H16: 0.5

Sheet Properties
A1: PropertyID | B1: PropertyName | C1: Address | D1: City | E1: State | F1: Zip | G1: UnitCount
A2: P001 | B2: Maple Apartments | C2: 123 Maple St | D2: Springfield | E2: IL | F2: 62701 | G2: 6
A3: P002 | B3: Riverbend Duplexes | C3: 88 River Rd | D3: Springfield | E3: IL | F3: 62704 | G3: 6
A4: P003 | B4: Pine View Homes | C4: 410 Pine Ave | D4: Springfield | E4: IL | F4: 62711 | G4: 6

Sheet Units
A1: UnitID | B1: PropertyID | C1: UnitNumber | D1: UnitType | E1: Bedrooms | F1: Bathrooms | G1: SquareFeet | H1: MarketRent | I1: Status
A2: U001 | B2: P001 | C2: 1 | D2: Apartment | E2: 1 | F2: 1 | G2: 650 | H2: 950 | I2: Vacant
A3: U002 | B3: P001 | C3: 2 | D3: Apartment | E3: 1 | F3: 1 | G3: 650 | H3: 950 | I3: Occupied
A4: U003 | B4: P001 | C4: 3 | D4: Apartment | E4: 2 | F4: 1.5 | G4: 900 | H4: 1250 | I4: Occupied
A5: U004 | B5: P001 | C5: 4 | D5: Apartment | E5: 2 | F5: 1.5 | G5: 900 | H5: 1250 | I5: Vacant
A6: U005 | B6: P001 | C6: 5 | D6: Apartment | E6: 2 | F6: 1.5 | G6: 900 | H6: 1250 | I6: Occupied
A7: U006 | B7: P001 | C7: 6 | D7: Apartment | E7: 3 | F7: 2 | G7: 1250 | H7: 1650 | I7: Occupied
A8: U007 | B8: P002 | C8: A | D8: Duplex | E8: 1 | F8: 1 | G8: 650 | H8: 950 | I8: Occupied
A9: U008 | B9: P002 | C9: B | D9: Duplex | E9: 1 | F9: 1 | G9: 650 | H9: 950 | I9: Occupied
A10: U009 | B10: P002 | C10: C | D10: Duplex | E10: 2 | F10: 1.5 | G10: 900 | H10: 1250 | I10: Vacant
A11: U010 | B11: P002 | C11: D | D11: Duplex | E11: 2 | F11: 1.5 | G11: 900 | H11: 1250 | I11: Occupied
A12: U011 | B12: P002 | C12: E | D12: Duplex | E12: 2 | F12: 1.5 | G12: 900 | H12: 1250 | I12: Occupied
A13: U012 | B13: P002 | C13: F | D13: Duplex | E13: 3 | F13: 2 | G13: 1250 | H13: 1650 | I13: Occupied
... A19: U018 | B19: P003 | C19: 6 | D19: Single-family | E19: 3 | F19: 2 | G19: 1250 | H19: 1650 | I19: Vacant

Sheet Tenants
A1: TenantID | B1: TenantName | C1: UnitID | D1: PropertyID | E1: LeaseStart | F1: LeaseEnd | G1: RentDueDay | H1: MonthlyRent | I1: SecurityDeposit | J1: TenantStatus
A2: T001 | B2: Quinn Garcia | C2: U002 | D2: P001 | E2: 45597 | F2: 45962 | G2: 1 | H2: 850 | I2: 850 | J2: Active
A3: T002 | B3: Finley Lee | C3: U003 | D3: P001 | E3: 45580 | F3: 45945 | G3: 1 | H3: 1250 | I3: 1250 | J3: Active
A4: T003 | B4: Alex Lee | C4: U005 | D4: P001 | E4: 45478 | F4: 45843 | G4: 1 | H4: 1150 | I4: 1150 | J4: Active
A5: T004 | B5: Alex Hall | C5: U006 | D5: P001 | E5: 45498 | F5: 45863 | G5: 1 | H5: 1550 | I5: 1550 | J5: Active
A6: T005 | B6: Finley Harris | C6: U007 | D6: P002 | E6: 45488 | F6: 45853 | G6: 1 | H6: 850 | I6: 850 | J6: Active
A7: T006 | B7: Avery Smith | C7: U008 | D7: P002 | E7: 45631 | F7: 45996 | G7: 1 | H7: 850 | I7: 850 | J7: Active
A8: T007 | B8: Skyler Anderson | C8: U010 | D8: P002 | E8: 45509 | F8: 45874 | G8: 1 | H8: 1250 | I8: 1250 | J8: Active
A9: T008 | B9: Drew Patel | C9: U011 | D9: P002 | E9: 45458 | F9: 45823 | G9: 1 | H9: 1250 | I9: 1250 | J9: Active
A10: T009 | B10: Hayden Thomas | C10: U012 | D10: P002 | E10: 45575 | F10: 45940 | G10: 1 | H10: 1650 | I10: 1650 | J10: Active
A11: T010 | B11: Emerson Hall | C11: U013 | D11: P003 | E11: 45458 | F11: 45823 | G11: 1 | H11: 950 | I11: 950 | J11: Active
A12: T011 | B12: Finley Martinez | C12: U014 | D12: P003 | E12: 45651 | F12: 46016 | G12: 1 | H12: 850 | I12: 850 | J12: Active
A13: T012 | B13: Hayden Davis | C13: U015 | D13: P003 | E13: 45597 | F13: 45962 | G13: 1 | H13: 1250 | I13: 1250 | J13: Active
... A15: T014 | B15: Reese Wilson | C15: U017 | D15: P003 | E15: 45560 | F15: 45925 | G15: 1 | H15: 1200 | I15: 1200 | J15: Active

Sheet RentPayments
A1: PaymentID | B1: TenantID | C1: UnitID | D1: PropertyID | E1: DueDate | F1: PaymentDate | G1: AmountDue | H1: AmountPaid | I1: PaymentStatus
A2: PM0001 | B2: T001 | C2: U002 | D2: P001 | E2: 45658 | F2: 45658 | G2: 850 | H2: 850 | I2: On Time
A3: PM0002 | B3: T001 | C3: U002 | D3: P001 | E3: 45689 | F3: 45689 | G3: 850 | H3: 850 | I3: On Time
A4: PM0003 | B4: T001 | C4: U002 | D4: P001 | E4: 45717 | F4: 45717 | G4: 850 | H4: 850 | I4: On Time
A5: PM0004 | B5: T001 | C5: U002 | D5: P001 | E5: 45748 | F5: 45758 | G5: 850 | H5: 850 | I5: Late
A6: PM0005 | B6: T001 | C6: U002 | D6: P001 | E6: 45778 | F6: 45778 | G6: 850 | H6: 850 | I6: On Time
A7: PM0006 | B7: T001 | C7: U002 | D7: P001 | E7: 45809 | F7: 45814 | G7: 850 | H7: 850 | I7: Late
A8: PM0007 | B8: T001 | C8: U002 | D8: P001 | E8: 45839 | F8: 45854 | G8: 850 | H8: 850 | I8: Late
A9: PM0008 | B9: T001 | C9: U002 | D9: P001 | E9: 45870 | F9: 45870 | G9: 850 | H9: 850 | I9: On Time
A10: PM0009 | B10: T001 | C10: U002 | D10: P001 | E10: 45901 | F10: 45901 | G10: 850 | H10: 850 | I10: On Time
A11: PM0010 | B11: T001 | C11: U002 | D11: P001 | E11: 45931 | F11: 45941 | G11: 850 | H11: 850 | I11: Late
A12: PM0011 | B12: T001 | C12: U002 | D12: P001 | E12: 45962 | F12: 45964 | G12: 850 | H12: 850 | I12: Late
A13: PM0012 | B13: T002 | C13: U003 | D13: P001 | E13: 45658 | F13: 45658 | G13: 1250 | H13: 1250 | I13: On Time
... A42: PM0041 | B42: T005 | C42: U007 | D42: P002 | E42: 45809 | F42: 45809 | G42: 850 | H42: 850 | I42: On Time
A43: PM0042 | B43: T005 | C43: U007 | D43: P002 | E43: 45839 | G43: 850 | H43: 0 | I43: Unpaid
A44: PM0043 | B44: T006 | C44: U008 | D44: P002 | E44: 45658 | F44: 45668 | G44: 850 | H44: 850 | I44: Late
A45: PM0044 | B45: T006 | C45: U008 | D45: P002 | E45: 45689 | F45: 45689 | G45: 850 | H45: 850 | I45: On Time
A46: PM0045 | B46: T006 | C46: U008 | D46: P002 | E46: 45717 | F46: 45717 | G46: 850 | H46: 850 | I46: On Time
A47: PM0046 | B47: T006 | C47: U008 | D47: P002 | E47: 45748 | F47: 45753 | G47: 850 | H47: 850 | I47: Late
A48: PM0047 | B48: T006 | C48: U008 | D48: P002 | E48: 45778 | F48: 45783 | G48: 850 | H48: 850 | I48: Late
A49: PM0048 | B49: T006 | C49: U008 | D49: P002 | E49: 45809 | F49: 45811 | G49: 850 | H49: 850 | I49: Late
A50: PM0049 | B50: T006 | C50: U008 | D50: P002 | E50: 45839 | F50: 45839 | G50: 850 | H50: 850 | I50: On Time
A51: PM0050 | B51: T006 | C51: U008 | D51: P002 | E51: 45870 | F51: 45872 | G51: 850 | H51: 850 | I51: Late
A52: PM0051 | B52: T006 | C52: U008 | D52: P002 | E52: 45901 | F52: 45911 | G52: 850 | H52: 850 | I52: Late
A53: PM0052 | B53: T006 | C53: U008 | D53: P002 | E53: 45931 | F53: 45931 | G53: 850 | H53: 850 | I53: On Time
A54: PM0053 | B54: T006 | C54: U008 | D54: P002 | E54: 45962 | F54: 45977 | G54: 850 | H54: 850 | I54: Late
A55: PM0054 | B55: T006 | C55: U008 | D55: P002 | E55: 45992 | F55: 45997 | G55: 850 | H55: 850 | I55: Late
... A61: PM0060 | B61: T007 | C61: U010 | D61: P002 | E61: 45809 | F61: 45811 | G61: 1250 | H61: 1250 | I61: Late
A62: PM0061 | B62: T007 | C62: U010 | D62: P002 | E62: 45839 | G62: 1250 | H62: 0 | I62: Unpaid
A63: PM0062 | B63: T007 | C63: U010 | D63: P002 | E63: 45870 | F63: 45872 | G63: 1250 | H63: 1250 | I63: Late
A64: PM0063 | B64: T008 | C64: U011 | D64: P002 | E64: 45658 | F64: 45660 | G64: 1250 | H64: 1250 | I64: Late
A65: PM0064 | B65: T008 | C65: U011 | D65: P002 | E65: 45689 | F65: 45699 | G65: 1250 | H65: 1250 | I65: Late
A66: PM0065 | B66: T008 | C66: U011 | D66: P002 | E66: 45717 | F66: 45727 | G66: 1250 | H66: 1250 | I66: Late
A67: PM0066 | B67: T008 | C67: U011 | D67: P002 | E67: 45748 | F67: 45748 | G67: 1250 | H67: 1250 | I67: On Time
A68: PM0067 | B68: T008 | C68: U011 | D68: P002 | E68: 45778 | F68: 45783 | G68: 1250 | H68: 937.5 | I68: Partial
A69: PM0068 | B69: T008 | C69: U011 | D69: P002 | E69: 45809 | F69: 45814 | G69: 1250 | H69: 1250 | I69: Late
A70: PM0069 | B70: T009 | C70: U012 | D70: P002 | E70: 45658 | F70: 45663 | G70: 1650 | H70: 1650 | I70: Late
A71: PM0070 | B71: T009 | C71: U012 | D71: P002 | E71: 45689 | F71: 45689 | G71: 1650 | H71: 1650 | I71: On Time
A72: PM0071 | B72: T009 | C72: U012 | D72: P002 | E72: 45717 | F72: 45717 | G72: 1650 | H72: 1650 | I72: On Time
A73: PM0072 | B73: T009 | C73: U012 | D73: P002 | E73: 45748 | F73: 45748 | G73: 1650 | H73: 1650 | I73: On Time
...

Sheet Maintenance
A1: MaintenanceID | B1: PropertyID | C1: UnitID | D1: RequestDate | E1: Category | F1: Description | G1: Vendor | H1: Cost | I1: Status
A2: M0001 | B2: P001 | C2: U001 | D2: 45926 | E2: General | F2: General service request | G2: Appliance Rescue | H2: 488.67 | I2: Completed
A3: M0002 | B3: P002 | C3: U007 | D3: 45822 | E3: Plumbing | F3: Plumbing service request | G3: Appliance Rescue | H3: 604.44 | I3: Completed
A4: M0003 | B4: P001 | C4: U004 | D4: 46001 | E4: General | F4: General service request | G4: CoolAir HVAC | H4: 458.46 | I4: Completed
A5: M0004 | B5: P002 | C5: U010 | D5: 45905 | E5: Electrical | F5: Electrical service request | G5: HandyPro | H5: 457.33 | I5: Completed
A6: M0005 | B6: P001 | C6: U006 | D6: 45949 | E6: Appliance | F6: Appliance service request | G6: HandyPro | H6: 390.06 | I6: Completed
A7: M0006 | B7: P002 | C7: U010 | D7: 45761 | E7: General | F7: General service request | G7: PestAway | H7: 451.46 | I7: Completed
A8: M0007 | B8: P003 | C8: U015 | D8: 45968 | E8: General | F8: General service request | G8: HandyPro | H8: 531.4 | I8: In Progress
A9: M0008 | B9: P001 | C9: U006 | D9: 45964 | E9: Appliance | F9: Appliance service request | G9: PestAway | H9: 456.72 | I9: Completed
A10: M0009 | B10: P001 | C10: U003 | D10: 45769 | E10: Appliance | F10: Appliance service request | G10: Spark Electric | H10: 538.77 | I10: Completed
A11: M0010 | B11: P001 | C11: U002 | D11: 45763 | E11: General | F11: General service request | G11: Ace Plumbing | H11: 336.86 | I11: Open
A12: M0011 | B12: P002 | C12: U007 | D12: 46014 | E12: HVAC | F12: HVAC service request | G12: HandyPro | H12: 304.8 | I12: Completed
A13: M0012 | B13: P001 | C13: U001 | D13: 45713 | E13: HVAC | F13: HVAC service request | G13: Spark Electric | H13: 176.13 | I13: In Progress
... A41: M0040 | B41: P003 | C41: U015 | D41: 45950 | E41: Pest Control | F41: Pest Control service request | G41: HandyPro | H41: 268.43 | I41: Completed

Sheet Expenses
A1: ExpenseID | B1: PropertyID | C1: ExpenseDate | D1: ExpenseType | E1: Amount | F1: Notes
A2: E0001 | B2: P001 | C2: 45814 | D2: HOA | E2: 222.42 | F2: HOA expense
A3: E0002 | B3: P001 | C3: 45788 | D3: Utilities | E3: 797.08 | F3: Utilities expense
A4: E0003 | B4: P001 | C4: 46000 | D4: Landscaping | E4: 48.73 | F4: Landscaping expense
A5: E0004 | B5: P001 | C5: 45750 | D5: Property Tax | E5: 659.26 | F5: Property Tax expense
A6: E0005 | B6: P001 | C6: 45887 | D6: Supplies | E6: 246.68 | F6: Supplies expense
A7: E0006 | B7: P001 | C7: 45890 | D7: Advertising | E7: 462.11 | F7: Advertising expense
A8: E0007 | B8: P001 | C8: 45660 | D8: Utilities | E8: 230.57 | F8: Utilities expense
A9: E0008 | B9: P001 | C9: 45999 | D9: Utilities | E9: 611.01 | F9: Utilities expense
A10: E0009 | B10: P001 | C10: 45824 | D10: Landscaping | E10: 496.59 | F10: Landscaping expense
A11: E0010 | B11: P001 | C11: 45862 | D11: Landscaping | E11: 324.48 | F11: Landscaping expense
A12: E0011 | B12: P001 | C12: 46006 | D12: Utilities | E12: 303.7 | F12: Utilities expense
A13: E0012 | B13: P001 | C13: 45751 | D13: Advertising | E13: 205.62 | F13: Advertising expense
... A73: E0072 | B73: P003 | C73: 45877 | D73: HOA | E73: 514.09 | F73: HOA expense
